<?xml version="1.0"?>
<robot name="origins">

  <material name="blue">
     <color rgba="0 0 0.8 1"/>
  </material>

  <material name="Red">
    <color rgba="0.8 0.0 0.0 1.0"/>
  </material>

  <material name="Black">
    <color rgba="0.0 0.0 0.0 1.0"/>
  </material>

  <link name="base_link">
    <visual>
      <geometry>
        <box size="0.4 0.2 0.05"/>
      </geometry>
      <origin rpy="0 0 0" xyz="0 0 0.05"/>
      <material name="blue"/>
    </visual>
    <collision>
       <geometry>
          <box size="0.4 0.2 0.05"/>
        </geometry>
       </collision>
     <inertial>
         <mass value="0.5"/>
         <inertia ixx="0.0067" ixy="0.0" ixz="0.0" iyy="0.0083" iyz="0.0" izz="0.0017"/>
     </inertial>
  </link>

  <link name="right_wheel">
    <visual>
      <geometry>
        <cylinder length="0.02" radius="0.025"/>
      </geometry>
      <origin rpy="1.57075 0 0" xyz="0 0 0"/>
      <material name="Black"/>
    </visual>
    <collision>
      <geometry>
        <cylinder length="0.02" radius="0.025"/>
      </geometry>
    </collision>
    <inertial>
      <mass value="0.1"/>
        <inertia ixx="0.000019" ixy="0.0" ixz="0.0" iyy="0.000019" iyz="0.0" izz="0.0000052"/>
    </inertial>
  </link>

  <joint name="wheel_0_joint" type="continuous">
    <parent link="base_link"/>
    <child link="right_wheel"/>
    <axis xyz="0 1 0"/>
    <origin xyz="0.15 0.11 0.025"/>
  </joint>

  <link name="left_wheel">
    <visual>
      <geometry>
        <cylinder length="0.02" radius="0.025"/>
      </geometry>
      <origin rpy="1.57075 0 0" xyz="0 0 0"/>
      <material name="Black"/>
    </visual>
    <collision>
      <geometry>
        <cylinder length="0.02" radius="0.025"/>
      </geometry>
    </collision>
    <inertial>
      <mass value="0.1"/>
        <inertia ixx="0.000019" ixy="0.0" ixz="0.0" iyy="0.000019" iyz="0.0" izz="0.0000052"/>
    </inertial>
  </link>

  <joint name="wheel_1_joint" type="continuous">
    <parent link="base_link"/>
    <child link="left_wheel"/>
    <axis xyz="0 1 0"/>
    <origin xyz="0.15 -0.11 0.025"/>
  </joint>

  <link name="caster_wheel_right">
    <visual>
      <origin rpy="0 0 0" xyz="0 0 0"/>
      <geometry>
        <sphere radius="0.0125"/>
      </geometry>
      <material name="Black"/>
    </visual>
    <collision>
      <geometry>
        <sphere radius="0.0125"/>
      </geometry>
    </collision>
    <inertial>
      <mass value="0.1"/>
        <inertia ixx="0.00001" ixy="0.0" ixz="0.0" iyy="0.00001" iyz="0.0" izz="0.00001"/>
    </inertial>  
  </link>

  <joint name="base_link_to_caster_wheel_right" type="continuous">
    <parent link="base_link"/>
    <child link="caster_wheel_right"/>
    <axis xyz="1 1 1"/>
    <origin rpy="0 0 0" xyz="-0.15 0.05 0.0125"/>
  </joint>

  <link name="caster_wheel_left">
    <visual>
      <origin rpy="0 0 0" xyz="0 0 0"/>
      <geometry>
        <sphere radius="0.0125"/>
      </geometry>
      <material name="Black"/>
    </visual>
    <collision>
      <geometry>
        <sphere radius="0.0125"/>
      </geometry>
    </collision>
    <inertial>
      <mass value="0.1"/>
        <inertia ixx="0.00001" ixy="0.0" ixz="0.0" iyy="0.00001" iyz="0.0" izz="0.00001"/>
    </inertial>  
  </link>

  <joint name="base_link_to_caster_wheel_left" type="continuous">
    <parent link="base_link"/>
    <child link="caster_wheel_left"/>
    <origin rpy="0 0 0" xyz="-0.15 -0.05 0.0125"/>
  </joint>

  
  <link name="kinect_link">
  <visual>
    <geometry>
      <box size="0.064 0.121 0.0381" />
    </geometry>
    <material name="Blue" />
  </visual>
  <inertial>
      <mass value="0.0001" />
      <origin xyz="0 0 0" />
      <inertia ixx="0.0001" ixy="0.0" ixz="0.0"
               iyy="0.0001" iyz="0.0" 
               izz="0.0001" />
  </inertial>
</link>

<joint name="kinect_depth_joint" type="fixed">
  <origin xyz="0 0.028 0" rpy="0 0 0" />
  <parent link="kinect_link" />
  <child link="kinect_depth_frame" />
</joint>

<link name="kinect_depth_frame">
  <inertial>
      <mass value="0.0001" />
      <origin xyz="0 0 0" />
      <inertia ixx="0.0001" ixy="0.0" ixz="0.0"
               iyy="0.0001" iyz="0.0" 
               izz="0.0001" />
  </inertial>
</link>

<joint name="depth_optical_joint" type="fixed">
  <origin xyz="0 0 0" rpy="-1.57075 0 -1.57075" />
  <parent link="kinect_depth_frame" />
  <child link="kinect_depth_optical_frame" />
</joint>

<link name="kinect_depth_optical_frame">
  <inertial>
      <mass value="0.0001" />
      <origin xyz="0 0 0" />
      <inertia ixx="0.0001" ixy="0.0" ixz="0.0"
               iyy="0.0001" iyz="0.0" 
               izz="0.0001" />
  </inertial>
</link>

<joint name="base_link_to_kinect_link" type="fixed">
    <parent link="base_link"/>
    <child link="kinect_link"/>
    <origin rpy="0 0 0" xyz="0 0 0.17"/>
  </joint>

  <transmission name="left_wheel_transmission">
  <type>transmission_interface/SimpleTransmission</type>
  <joint name="wheel_1_joint">
    <hardwareInterface>hardware_interface/JointStateController</hardwareInterface>  
  </joint>
  <actuator name="left_wheel_actuator">
    <mechanicalReduction>7</mechanicalReduction>
    <hardwareInterface>VelocityJointInterface</hardwareInterface>
  </actuator>
</transmission>
 
<transmission name="right_wheel_transmission">
  <type>transmission_interface/SimpleTransmission</type>
  <joint name="wheel_0_joint">
    <hardwareInterface>hardware_interface/JointStateController</hardwareInterface>  
  </joint>
  <actuator name="right_wheel_actuator">
    <mechanicalReduction>7</mechanicalReduction>
    <hardwareInterface>VelocityJointInterface</hardwareInterface>
  </actuator>
</transmission>


</robot>

